[2022-04-11 13:26:26,963] {taskinstance.py:1032} INFO - Dependencies all met for <TaskInstance: download_data_dag.download_data scheduled__2019-01-01T00:00:00+00:00 [queued]>
[2022-04-11 13:26:26,974] {taskinstance.py:1032} INFO - Dependencies all met for <TaskInstance: download_data_dag.download_data scheduled__2019-01-01T00:00:00+00:00 [queued]>
[2022-04-11 13:26:26,975] {taskinstance.py:1238} INFO - 
--------------------------------------------------------------------------------
[2022-04-11 13:26:26,975] {taskinstance.py:1239} INFO - Starting attempt 3 of 3
[2022-04-11 13:26:26,975] {taskinstance.py:1240} INFO - 
--------------------------------------------------------------------------------
[2022-04-11 13:26:26,988] {taskinstance.py:1259} INFO - Executing <Task(PythonOperator): download_data> on 2019-01-01 00:00:00+00:00
[2022-04-11 13:26:26,998] {standard_task_runner.py:52} INFO - Started process 323629 to run task
[2022-04-11 13:26:27,004] {standard_task_runner.py:76} INFO - Running: ['***', 'tasks', 'run', 'download_data_dag', 'download_data', 'scheduled__2019-01-01T00:00:00+00:00', '--job-id', '1665', '--raw', '--subdir', 'DAGS_FOLDER/nfl_to_gcs.py', '--cfg-path', '/tmp/tmpgxok71xf', '--error-file', '/tmp/tmpbwgmkt5h']
[2022-04-11 13:26:27,006] {standard_task_runner.py:77} INFO - Job 1665: Subtask download_data
[2022-04-11 13:26:27,075] {logging_mixin.py:109} INFO - Running <TaskInstance: download_data_dag.download_data scheduled__2019-01-01T00:00:00+00:00 [running]> on host 4ed3eda454fd
[2022-04-11 13:26:27,145] {taskinstance.py:1426} INFO - Exporting the following env vars:
AIRFLOW_CTX_DAG_OWNER=***
AIRFLOW_CTX_DAG_ID=download_data_dag
AIRFLOW_CTX_TASK_ID=download_data
AIRFLOW_CTX_EXECUTION_DATE=2019-01-01T00:00:00+00:00
AIRFLOW_CTX_DAG_RUN_ID=scheduled__2019-01-01T00:00:00+00:00
[2022-04-11 13:26:27,146] {taskinstance.py:1700} ERROR - Task failed with exception
Traceback (most recent call last):
  File "/home/airflow/.local/lib/python3.7/site-packages/airflow/models/taskinstance.py", line 1329, in _run_raw_task
    self._execute_task_with_callbacks(context)
  File "/home/airflow/.local/lib/python3.7/site-packages/airflow/models/taskinstance.py", line 1455, in _execute_task_with_callbacks
    result = self._execute_task(context, self.task)
  File "/home/airflow/.local/lib/python3.7/site-packages/airflow/models/taskinstance.py", line 1511, in _execute_task
    result = execute_callable(context=context)
  File "/home/airflow/.local/lib/python3.7/site-packages/airflow/operators/python.py", line 174, in execute
    return_value = self.execute_callable()
  File "/home/airflow/.local/lib/python3.7/site-packages/airflow/operators/python.py", line 185, in execute_callable
    return self.python_callable(*self.op_args, **self.op_kwargs)
  File "/opt/airflow/dags/nfl_to_gcs.py", line 25, in download_nfl_data
    schedule_data = pa.Table.from_pandas(nfl.load_schedule_data(year=year))
NameError: name 'pa' is not defined
[2022-04-11 13:26:27,162] {taskinstance.py:1277} INFO - Marking task as FAILED. dag_id=download_data_dag, task_id=download_data, execution_date=20190101T000000, start_date=20220411T132626, end_date=20220411T132627
[2022-04-11 13:26:27,177] {standard_task_runner.py:92} ERROR - Failed to execute job 1665 for task download_data
Traceback (most recent call last):
  File "/home/airflow/.local/lib/python3.7/site-packages/airflow/task/task_runner/standard_task_runner.py", line 85, in _start_by_fork
    args.func(args, dag=self.dag)
  File "/home/airflow/.local/lib/python3.7/site-packages/airflow/cli/cli_parser.py", line 48, in command
    return func(*args, **kwargs)
  File "/home/airflow/.local/lib/python3.7/site-packages/airflow/utils/cli.py", line 92, in wrapper
    return f(*args, **kwargs)
  File "/home/airflow/.local/lib/python3.7/site-packages/airflow/cli/commands/task_command.py", line 298, in task_run
    _run_task_by_selected_method(args, dag, ti)
  File "/home/airflow/.local/lib/python3.7/site-packages/airflow/cli/commands/task_command.py", line 107, in _run_task_by_selected_method
    _run_raw_task(args, ti)
  File "/home/airflow/.local/lib/python3.7/site-packages/airflow/cli/commands/task_command.py", line 184, in _run_raw_task
    error_file=args.error_file,
  File "/home/airflow/.local/lib/python3.7/site-packages/airflow/utils/session.py", line 70, in wrapper
    return func(*args, session=session, **kwargs)
  File "/home/airflow/.local/lib/python3.7/site-packages/airflow/models/taskinstance.py", line 1329, in _run_raw_task
    self._execute_task_with_callbacks(context)
  File "/home/airflow/.local/lib/python3.7/site-packages/airflow/models/taskinstance.py", line 1455, in _execute_task_with_callbacks
    result = self._execute_task(context, self.task)
  File "/home/airflow/.local/lib/python3.7/site-packages/airflow/models/taskinstance.py", line 1511, in _execute_task
    result = execute_callable(context=context)
  File "/home/airflow/.local/lib/python3.7/site-packages/airflow/operators/python.py", line 174, in execute
    return_value = self.execute_callable()
  File "/home/airflow/.local/lib/python3.7/site-packages/airflow/operators/python.py", line 185, in execute_callable
    return self.python_callable(*self.op_args, **self.op_kwargs)
  File "/opt/airflow/dags/nfl_to_gcs.py", line 25, in download_nfl_data
    schedule_data = pa.Table.from_pandas(nfl.load_schedule_data(year=year))
NameError: name 'pa' is not defined
[2022-04-11 13:26:27,216] {local_task_job.py:154} INFO - Task exited with return code 1
[2022-04-11 13:26:27,254] {local_task_job.py:264} INFO - 0 downstream tasks scheduled from follow-on schedule check
