[2022-04-11 17:33:00,925] {taskinstance.py:1032} INFO - Dependencies all met for <TaskInstance: schedule_data.rm_task scheduled__2019-01-01T00:00:00+00:00 [queued]>
[2022-04-11 17:33:00,937] {taskinstance.py:1032} INFO - Dependencies all met for <TaskInstance: schedule_data.rm_task scheduled__2019-01-01T00:00:00+00:00 [queued]>
[2022-04-11 17:33:00,937] {taskinstance.py:1238} INFO - 
--------------------------------------------------------------------------------
[2022-04-11 17:33:00,937] {taskinstance.py:1239} INFO - Starting attempt 4 of 4
[2022-04-11 17:33:00,937] {taskinstance.py:1240} INFO - 
--------------------------------------------------------------------------------
[2022-04-11 17:33:00,952] {taskinstance.py:1259} INFO - Executing <Task(BashOperator): rm_task> on 2019-01-01 00:00:00+00:00
[2022-04-11 17:33:00,959] {standard_task_runner.py:52} INFO - Started process 344154 to run task
[2022-04-11 17:33:00,965] {standard_task_runner.py:76} INFO - Running: ['***', 'tasks', 'run', 'schedule_data', 'rm_task', 'scheduled__2019-01-01T00:00:00+00:00', '--job-id', '1690', '--raw', '--subdir', 'DAGS_FOLDER/nfl_to_gcs.py', '--cfg-path', '/tmp/tmpk2zb9db1', '--error-file', '/tmp/tmp1ypkv5zm']
[2022-04-11 17:33:00,966] {standard_task_runner.py:77} INFO - Job 1690: Subtask rm_task
[2022-04-11 17:33:01,029] {logging_mixin.py:109} INFO - Running <TaskInstance: schedule_data.rm_task scheduled__2019-01-01T00:00:00+00:00 [running]> on host 4ed3eda454fd
[2022-04-11 17:33:01,104] {taskinstance.py:1426} INFO - Exporting the following env vars:
AIRFLOW_CTX_DAG_OWNER=***
AIRFLOW_CTX_DAG_ID=schedule_data
AIRFLOW_CTX_TASK_ID=rm_task
AIRFLOW_CTX_EXECUTION_DATE=2019-01-01T00:00:00+00:00
AIRFLOW_CTX_DAG_RUN_ID=scheduled__2019-01-01T00:00:00+00:00
[2022-04-11 17:33:01,105] {subprocess.py:62} INFO - Tmp dir root location: 
 /tmp
[2022-04-11 17:33:01,106] {subprocess.py:74} INFO - Running command: ['bash', '-c', 'rm None']
[2022-04-11 17:33:01,122] {subprocess.py:85} INFO - Output:
[2022-04-11 17:33:01,126] {subprocess.py:89} INFO - rm: cannot remove 'None': No such file or directory
[2022-04-11 17:33:01,127] {subprocess.py:93} INFO - Command exited with return code 1
[2022-04-11 17:33:01,143] {taskinstance.py:1700} ERROR - Task failed with exception
Traceback (most recent call last):
  File "/home/airflow/.local/lib/python3.7/site-packages/airflow/models/taskinstance.py", line 1329, in _run_raw_task
    self._execute_task_with_callbacks(context)
  File "/home/airflow/.local/lib/python3.7/site-packages/airflow/models/taskinstance.py", line 1455, in _execute_task_with_callbacks
    result = self._execute_task(context, self.task)
  File "/home/airflow/.local/lib/python3.7/site-packages/airflow/models/taskinstance.py", line 1511, in _execute_task
    result = execute_callable(context=context)
  File "/home/airflow/.local/lib/python3.7/site-packages/airflow/operators/bash.py", line 188, in execute
    f'Bash command failed. The command returned a non-zero exit code {result.exit_code}.'
airflow.exceptions.AirflowException: Bash command failed. The command returned a non-zero exit code 1.
[2022-04-11 17:33:01,150] {taskinstance.py:1277} INFO - Marking task as FAILED. dag_id=schedule_data, task_id=rm_task, execution_date=20190101T000000, start_date=20220411T173300, end_date=20220411T173301
[2022-04-11 17:33:01,164] {standard_task_runner.py:92} ERROR - Failed to execute job 1690 for task rm_task
Traceback (most recent call last):
  File "/home/airflow/.local/lib/python3.7/site-packages/airflow/task/task_runner/standard_task_runner.py", line 85, in _start_by_fork
    args.func(args, dag=self.dag)
  File "/home/airflow/.local/lib/python3.7/site-packages/airflow/cli/cli_parser.py", line 48, in command
    return func(*args, **kwargs)
  File "/home/airflow/.local/lib/python3.7/site-packages/airflow/utils/cli.py", line 92, in wrapper
    return f(*args, **kwargs)
  File "/home/airflow/.local/lib/python3.7/site-packages/airflow/cli/commands/task_command.py", line 298, in task_run
    _run_task_by_selected_method(args, dag, ti)
  File "/home/airflow/.local/lib/python3.7/site-packages/airflow/cli/commands/task_command.py", line 107, in _run_task_by_selected_method
    _run_raw_task(args, ti)
  File "/home/airflow/.local/lib/python3.7/site-packages/airflow/cli/commands/task_command.py", line 184, in _run_raw_task
    error_file=args.error_file,
  File "/home/airflow/.local/lib/python3.7/site-packages/airflow/utils/session.py", line 70, in wrapper
    return func(*args, session=session, **kwargs)
  File "/home/airflow/.local/lib/python3.7/site-packages/airflow/models/taskinstance.py", line 1329, in _run_raw_task
    self._execute_task_with_callbacks(context)
  File "/home/airflow/.local/lib/python3.7/site-packages/airflow/models/taskinstance.py", line 1455, in _execute_task_with_callbacks
    result = self._execute_task(context, self.task)
  File "/home/airflow/.local/lib/python3.7/site-packages/airflow/models/taskinstance.py", line 1511, in _execute_task
    result = execute_callable(context=context)
  File "/home/airflow/.local/lib/python3.7/site-packages/airflow/operators/bash.py", line 188, in execute
    f'Bash command failed. The command returned a non-zero exit code {result.exit_code}.'
airflow.exceptions.AirflowException: Bash command failed. The command returned a non-zero exit code 1.
[2022-04-11 17:33:01,177] {local_task_job.py:154} INFO - Task exited with return code 1
[2022-04-11 17:33:01,211] {local_task_job.py:264} INFO - 0 downstream tasks scheduled from follow-on schedule check
[2022-04-11 19:12:56,609] {taskinstance.py:1032} INFO - Dependencies all met for <TaskInstance: schedule_data.rm_task scheduled__2019-01-01T00:00:00+00:00 [queued]>
[2022-04-11 19:12:56,624] {taskinstance.py:1032} INFO - Dependencies all met for <TaskInstance: schedule_data.rm_task scheduled__2019-01-01T00:00:00+00:00 [queued]>
[2022-04-11 19:12:56,625] {taskinstance.py:1238} INFO - 
--------------------------------------------------------------------------------
[2022-04-11 19:12:56,625] {taskinstance.py:1239} INFO - Starting attempt 4 of 4
[2022-04-11 19:12:56,625] {taskinstance.py:1240} INFO - 
--------------------------------------------------------------------------------
[2022-04-11 19:12:56,638] {taskinstance.py:1259} INFO - Executing <Task(BashOperator): rm_task> on 2019-01-01 00:00:00+00:00
[2022-04-11 19:12:56,645] {standard_task_runner.py:52} INFO - Started process 352627 to run task
[2022-04-11 19:12:56,650] {standard_task_runner.py:76} INFO - Running: ['***', 'tasks', 'run', 'schedule_data', 'rm_task', 'scheduled__2019-01-01T00:00:00+00:00', '--job-id', '1714', '--raw', '--subdir', 'DAGS_FOLDER/nfl_to_gcs.py', '--cfg-path', '/tmp/tmp4ibnw5w2', '--error-file', '/tmp/tmp40psuagz']
[2022-04-11 19:12:56,651] {standard_task_runner.py:77} INFO - Job 1714: Subtask rm_task
[2022-04-11 19:12:56,713] {logging_mixin.py:109} INFO - Running <TaskInstance: schedule_data.rm_task scheduled__2019-01-01T00:00:00+00:00 [running]> on host 4ed3eda454fd
[2022-04-11 19:12:56,785] {taskinstance.py:1426} INFO - Exporting the following env vars:
AIRFLOW_CTX_DAG_OWNER=***
AIRFLOW_CTX_DAG_ID=schedule_data
AIRFLOW_CTX_TASK_ID=rm_task
AIRFLOW_CTX_EXECUTION_DATE=2019-01-01T00:00:00+00:00
AIRFLOW_CTX_DAG_RUN_ID=scheduled__2019-01-01T00:00:00+00:00
[2022-04-11 19:12:56,786] {subprocess.py:62} INFO - Tmp dir root location: 
 /tmp
[2022-04-11 19:12:56,787] {subprocess.py:74} INFO - Running command: ['bash', '-c', 'rm "None"']
[2022-04-11 19:12:56,802] {subprocess.py:85} INFO - Output:
[2022-04-11 19:12:56,806] {subprocess.py:89} INFO - rm: cannot remove 'None': No such file or directory
[2022-04-11 19:12:56,807] {subprocess.py:93} INFO - Command exited with return code 1
[2022-04-11 19:12:56,822] {taskinstance.py:1700} ERROR - Task failed with exception
Traceback (most recent call last):
  File "/home/airflow/.local/lib/python3.7/site-packages/airflow/models/taskinstance.py", line 1329, in _run_raw_task
    self._execute_task_with_callbacks(context)
  File "/home/airflow/.local/lib/python3.7/site-packages/airflow/models/taskinstance.py", line 1455, in _execute_task_with_callbacks
    result = self._execute_task(context, self.task)
  File "/home/airflow/.local/lib/python3.7/site-packages/airflow/models/taskinstance.py", line 1511, in _execute_task
    result = execute_callable(context=context)
  File "/home/airflow/.local/lib/python3.7/site-packages/airflow/operators/bash.py", line 188, in execute
    f'Bash command failed. The command returned a non-zero exit code {result.exit_code}.'
airflow.exceptions.AirflowException: Bash command failed. The command returned a non-zero exit code 1.
[2022-04-11 19:12:56,830] {taskinstance.py:1277} INFO - Marking task as FAILED. dag_id=schedule_data, task_id=rm_task, execution_date=20190101T000000, start_date=20220411T191256, end_date=20220411T191256
[2022-04-11 19:12:56,843] {standard_task_runner.py:92} ERROR - Failed to execute job 1714 for task rm_task
Traceback (most recent call last):
  File "/home/airflow/.local/lib/python3.7/site-packages/airflow/task/task_runner/standard_task_runner.py", line 85, in _start_by_fork
    args.func(args, dag=self.dag)
  File "/home/airflow/.local/lib/python3.7/site-packages/airflow/cli/cli_parser.py", line 48, in command
    return func(*args, **kwargs)
  File "/home/airflow/.local/lib/python3.7/site-packages/airflow/utils/cli.py", line 92, in wrapper
    return f(*args, **kwargs)
  File "/home/airflow/.local/lib/python3.7/site-packages/airflow/cli/commands/task_command.py", line 298, in task_run
    _run_task_by_selected_method(args, dag, ti)
  File "/home/airflow/.local/lib/python3.7/site-packages/airflow/cli/commands/task_command.py", line 107, in _run_task_by_selected_method
    _run_raw_task(args, ti)
  File "/home/airflow/.local/lib/python3.7/site-packages/airflow/cli/commands/task_command.py", line 184, in _run_raw_task
    error_file=args.error_file,
  File "/home/airflow/.local/lib/python3.7/site-packages/airflow/utils/session.py", line 70, in wrapper
    return func(*args, session=session, **kwargs)
  File "/home/airflow/.local/lib/python3.7/site-packages/airflow/models/taskinstance.py", line 1329, in _run_raw_task
    self._execute_task_with_callbacks(context)
  File "/home/airflow/.local/lib/python3.7/site-packages/airflow/models/taskinstance.py", line 1455, in _execute_task_with_callbacks
    result = self._execute_task(context, self.task)
  File "/home/airflow/.local/lib/python3.7/site-packages/airflow/models/taskinstance.py", line 1511, in _execute_task
    result = execute_callable(context=context)
  File "/home/airflow/.local/lib/python3.7/site-packages/airflow/operators/bash.py", line 188, in execute
    f'Bash command failed. The command returned a non-zero exit code {result.exit_code}.'
airflow.exceptions.AirflowException: Bash command failed. The command returned a non-zero exit code 1.
[2022-04-11 19:12:56,862] {local_task_job.py:154} INFO - Task exited with return code 1
[2022-04-11 19:12:56,895] {local_task_job.py:264} INFO - 0 downstream tasks scheduled from follow-on schedule check
