[2022-04-11 17:37:15,248] {taskinstance.py:1032} INFO - Dependencies all met for <TaskInstance: schedule_data.rm_task scheduled__2019-01-01T00:00:00+00:00 [queued]>
[2022-04-11 17:37:15,258] {taskinstance.py:1032} INFO - Dependencies all met for <TaskInstance: schedule_data.rm_task scheduled__2019-01-01T00:00:00+00:00 [queued]>
[2022-04-11 17:37:15,258] {taskinstance.py:1238} INFO - 
--------------------------------------------------------------------------------
[2022-04-11 17:37:15,258] {taskinstance.py:1239} INFO - Starting attempt 6 of 6
[2022-04-11 17:37:15,258] {taskinstance.py:1240} INFO - 
--------------------------------------------------------------------------------
[2022-04-11 17:37:15,270] {taskinstance.py:1259} INFO - Executing <Task(BashOperator): rm_task> on 2019-01-01 00:00:00+00:00
[2022-04-11 17:37:15,277] {standard_task_runner.py:52} INFO - Started process 344527 to run task
[2022-04-11 17:37:15,282] {standard_task_runner.py:76} INFO - Running: ['***', 'tasks', 'run', 'schedule_data', 'rm_task', 'scheduled__2019-01-01T00:00:00+00:00', '--job-id', '1692', '--raw', '--subdir', 'DAGS_FOLDER/nfl_to_gcs.py', '--cfg-path', '/tmp/tmpp318e3nr', '--error-file', '/tmp/tmprux55sv6']
[2022-04-11 17:37:15,283] {standard_task_runner.py:77} INFO - Job 1692: Subtask rm_task
[2022-04-11 17:37:15,342] {logging_mixin.py:109} INFO - Running <TaskInstance: schedule_data.rm_task scheduled__2019-01-01T00:00:00+00:00 [running]> on host 4ed3eda454fd
[2022-04-11 17:37:15,382] {taskinstance.py:1700} ERROR - Task failed with exception
Traceback (most recent call last):
  File "/home/airflow/.local/lib/python3.7/site-packages/airflow/models/taskinstance.py", line 1329, in _run_raw_task
    self._execute_task_with_callbacks(context)
  File "/home/airflow/.local/lib/python3.7/site-packages/airflow/models/taskinstance.py", line 1418, in _execute_task_with_callbacks
    self.render_templates(context=context)
  File "/home/airflow/.local/lib/python3.7/site-packages/airflow/models/taskinstance.py", line 1992, in render_templates
    self.task.render_template_fields(context)
  File "/home/airflow/.local/lib/python3.7/site-packages/airflow/models/baseoperator.py", line 1061, in render_template_fields
    self._do_render_template_fields(self, self.template_fields, context, jinja_env, set())
  File "/home/airflow/.local/lib/python3.7/site-packages/airflow/models/baseoperator.py", line 1074, in _do_render_template_fields
    rendered_content = self.render_template(content, context, jinja_env, seen_oids)
  File "/home/airflow/.local/lib/python3.7/site-packages/airflow/models/baseoperator.py", line 1110, in render_template
    template = jinja_env.from_string(content)
  File "/home/airflow/.local/lib/python3.7/site-packages/jinja2/environment.py", line 1092, in from_string
    return cls.from_code(self, self.compile(source), gs, None)
  File "/home/airflow/.local/lib/python3.7/site-packages/jinja2/environment.py", line 757, in compile
    self.handle_exception(source=source_hint)
  File "/home/airflow/.local/lib/python3.7/site-packages/jinja2/environment.py", line 925, in handle_exception
    raise rewrite_traceback_stack(source=source)
  File "<unknown>", line 1, in template
jinja2.exceptions.TemplateSyntaxError: unexpected char '\\' at 6
[2022-04-11 17:37:15,397] {taskinstance.py:1277} INFO - Marking task as FAILED. dag_id=schedule_data, task_id=rm_task, execution_date=20190101T000000, start_date=20220411T173715, end_date=20220411T173715
[2022-04-11 17:37:15,411] {standard_task_runner.py:92} ERROR - Failed to execute job 1692 for task rm_task
Traceback (most recent call last):
  File "/home/airflow/.local/lib/python3.7/site-packages/airflow/task/task_runner/standard_task_runner.py", line 85, in _start_by_fork
    args.func(args, dag=self.dag)
  File "/home/airflow/.local/lib/python3.7/site-packages/airflow/cli/cli_parser.py", line 48, in command
    return func(*args, **kwargs)
  File "/home/airflow/.local/lib/python3.7/site-packages/airflow/utils/cli.py", line 92, in wrapper
    return f(*args, **kwargs)
  File "/home/airflow/.local/lib/python3.7/site-packages/airflow/cli/commands/task_command.py", line 298, in task_run
    _run_task_by_selected_method(args, dag, ti)
  File "/home/airflow/.local/lib/python3.7/site-packages/airflow/cli/commands/task_command.py", line 107, in _run_task_by_selected_method
    _run_raw_task(args, ti)
  File "/home/airflow/.local/lib/python3.7/site-packages/airflow/cli/commands/task_command.py", line 184, in _run_raw_task
    error_file=args.error_file,
  File "/home/airflow/.local/lib/python3.7/site-packages/airflow/utils/session.py", line 70, in wrapper
    return func(*args, session=session, **kwargs)
  File "/home/airflow/.local/lib/python3.7/site-packages/airflow/models/taskinstance.py", line 1329, in _run_raw_task
    self._execute_task_with_callbacks(context)
  File "/home/airflow/.local/lib/python3.7/site-packages/airflow/models/taskinstance.py", line 1418, in _execute_task_with_callbacks
    self.render_templates(context=context)
  File "/home/airflow/.local/lib/python3.7/site-packages/airflow/models/taskinstance.py", line 1992, in render_templates
    self.task.render_template_fields(context)
  File "/home/airflow/.local/lib/python3.7/site-packages/airflow/models/baseoperator.py", line 1061, in render_template_fields
    self._do_render_template_fields(self, self.template_fields, context, jinja_env, set())
  File "/home/airflow/.local/lib/python3.7/site-packages/airflow/models/baseoperator.py", line 1074, in _do_render_template_fields
    rendered_content = self.render_template(content, context, jinja_env, seen_oids)
  File "/home/airflow/.local/lib/python3.7/site-packages/airflow/models/baseoperator.py", line 1110, in render_template
    template = jinja_env.from_string(content)
  File "/home/airflow/.local/lib/python3.7/site-packages/jinja2/environment.py", line 1092, in from_string
    return cls.from_code(self, self.compile(source), gs, None)
  File "/home/airflow/.local/lib/python3.7/site-packages/jinja2/environment.py", line 757, in compile
    self.handle_exception(source=source_hint)
  File "/home/airflow/.local/lib/python3.7/site-packages/jinja2/environment.py", line 925, in handle_exception
    raise rewrite_traceback_stack(source=source)
  File "<unknown>", line 1, in template
jinja2.exceptions.TemplateSyntaxError: unexpected char '\\' at 6
[2022-04-11 17:37:15,454] {local_task_job.py:154} INFO - Task exited with return code 1
[2022-04-11 17:37:15,488] {local_task_job.py:264} INFO - 0 downstream tasks scheduled from follow-on schedule check
[2022-04-11 19:15:58,606] {taskinstance.py:1032} INFO - Dependencies all met for <TaskInstance: schedule_data.rm_task scheduled__2019-01-01T00:00:00+00:00 [queued]>
[2022-04-11 19:15:58,618] {taskinstance.py:1032} INFO - Dependencies all met for <TaskInstance: schedule_data.rm_task scheduled__2019-01-01T00:00:00+00:00 [queued]>
[2022-04-11 19:15:58,618] {taskinstance.py:1238} INFO - 
--------------------------------------------------------------------------------
[2022-04-11 19:15:58,618] {taskinstance.py:1239} INFO - Starting attempt 6 of 6
[2022-04-11 19:15:58,619] {taskinstance.py:1240} INFO - 
--------------------------------------------------------------------------------
[2022-04-11 19:15:58,636] {taskinstance.py:1259} INFO - Executing <Task(BashOperator): rm_task> on 2019-01-01 00:00:00+00:00
[2022-04-11 19:15:58,644] {standard_task_runner.py:52} INFO - Started process 352895 to run task
[2022-04-11 19:15:58,649] {standard_task_runner.py:76} INFO - Running: ['***', 'tasks', 'run', 'schedule_data', 'rm_task', 'scheduled__2019-01-01T00:00:00+00:00', '--job-id', '1716', '--raw', '--subdir', 'DAGS_FOLDER/nfl_to_gcs.py', '--cfg-path', '/tmp/tmp2s4akjl9', '--error-file', '/tmp/tmpuc0mbtt7']
[2022-04-11 19:15:58,651] {standard_task_runner.py:77} INFO - Job 1716: Subtask rm_task
[2022-04-11 19:15:58,713] {logging_mixin.py:109} INFO - Running <TaskInstance: schedule_data.rm_task scheduled__2019-01-01T00:00:00+00:00 [running]> on host 4ed3eda454fd
[2022-04-11 19:15:58,794] {taskinstance.py:1426} INFO - Exporting the following env vars:
AIRFLOW_CTX_DAG_OWNER=***
AIRFLOW_CTX_DAG_ID=schedule_data
AIRFLOW_CTX_TASK_ID=rm_task
AIRFLOW_CTX_EXECUTION_DATE=2019-01-01T00:00:00+00:00
AIRFLOW_CTX_DAG_RUN_ID=scheduled__2019-01-01T00:00:00+00:00
[2022-04-11 19:15:58,796] {subprocess.py:62} INFO - Tmp dir root location: 
 /tmp
[2022-04-11 19:15:58,797] {subprocess.py:74} INFO - Running command: ['bash', '-c', 'rm "/opt/***/schedule_data_2019.parquet"']
[2022-04-11 19:15:58,837] {subprocess.py:85} INFO - Output:
[2022-04-11 19:15:58,842] {subprocess.py:93} INFO - Command exited with return code 0
[2022-04-11 19:15:58,873] {taskinstance.py:1277} INFO - Marking task as SUCCESS. dag_id=schedule_data, task_id=rm_task, execution_date=20190101T000000, start_date=20220411T191558, end_date=20220411T191558
[2022-04-11 19:15:58,902] {local_task_job.py:154} INFO - Task exited with return code 0
[2022-04-11 19:15:58,935] {local_task_job.py:264} INFO - 0 downstream tasks scheduled from follow-on schedule check
