[2022-04-11 17:37:57,661] {taskinstance.py:1032} INFO - Dependencies all met for <TaskInstance: schedule_data.rm_task scheduled__2019-01-01T00:00:00+00:00 [queued]>
[2022-04-11 17:37:57,675] {taskinstance.py:1032} INFO - Dependencies all met for <TaskInstance: schedule_data.rm_task scheduled__2019-01-01T00:00:00+00:00 [queued]>
[2022-04-11 17:37:57,676] {taskinstance.py:1238} INFO - 
--------------------------------------------------------------------------------
[2022-04-11 17:37:57,676] {taskinstance.py:1239} INFO - Starting attempt 8 of 8
[2022-04-11 17:37:57,676] {taskinstance.py:1240} INFO - 
--------------------------------------------------------------------------------
[2022-04-11 17:37:57,692] {taskinstance.py:1259} INFO - Executing <Task(BashOperator): rm_task> on 2019-01-01 00:00:00+00:00
[2022-04-11 17:37:57,699] {standard_task_runner.py:52} INFO - Started process 344615 to run task
[2022-04-11 17:37:57,704] {standard_task_runner.py:76} INFO - Running: ['***', 'tasks', 'run', 'schedule_data', 'rm_task', 'scheduled__2019-01-01T00:00:00+00:00', '--job-id', '1694', '--raw', '--subdir', 'DAGS_FOLDER/nfl_to_gcs.py', '--cfg-path', '/tmp/tmpkl35bomz', '--error-file', '/tmp/tmp1vxqwren']
[2022-04-11 17:37:57,705] {standard_task_runner.py:77} INFO - Job 1694: Subtask rm_task
[2022-04-11 17:37:57,766] {logging_mixin.py:109} INFO - Running <TaskInstance: schedule_data.rm_task scheduled__2019-01-01T00:00:00+00:00 [running]> on host 4ed3eda454fd
[2022-04-11 17:37:57,836] {taskinstance.py:1426} INFO - Exporting the following env vars:
AIRFLOW_CTX_DAG_OWNER=***
AIRFLOW_CTX_DAG_ID=schedule_data
AIRFLOW_CTX_TASK_ID=rm_task
AIRFLOW_CTX_EXECUTION_DATE=2019-01-01T00:00:00+00:00
AIRFLOW_CTX_DAG_RUN_ID=scheduled__2019-01-01T00:00:00+00:00
[2022-04-11 17:37:57,837] {subprocess.py:62} INFO - Tmp dir root location: 
 /tmp
[2022-04-11 17:37:57,838] {subprocess.py:74} INFO - Running command: ['bash', '-c', 'rm None']
[2022-04-11 17:37:57,852] {subprocess.py:85} INFO - Output:
[2022-04-11 17:37:57,857] {subprocess.py:89} INFO - rm: cannot remove 'None': No such file or directory
[2022-04-11 17:37:57,857] {subprocess.py:93} INFO - Command exited with return code 1
[2022-04-11 17:37:57,874] {taskinstance.py:1700} ERROR - Task failed with exception
Traceback (most recent call last):
  File "/home/airflow/.local/lib/python3.7/site-packages/airflow/models/taskinstance.py", line 1329, in _run_raw_task
    self._execute_task_with_callbacks(context)
  File "/home/airflow/.local/lib/python3.7/site-packages/airflow/models/taskinstance.py", line 1455, in _execute_task_with_callbacks
    result = self._execute_task(context, self.task)
  File "/home/airflow/.local/lib/python3.7/site-packages/airflow/models/taskinstance.py", line 1511, in _execute_task
    result = execute_callable(context=context)
  File "/home/airflow/.local/lib/python3.7/site-packages/airflow/operators/bash.py", line 188, in execute
    f'Bash command failed. The command returned a non-zero exit code {result.exit_code}.'
airflow.exceptions.AirflowException: Bash command failed. The command returned a non-zero exit code 1.
[2022-04-11 17:37:57,881] {taskinstance.py:1277} INFO - Marking task as FAILED. dag_id=schedule_data, task_id=rm_task, execution_date=20190101T000000, start_date=20220411T173757, end_date=20220411T173757
[2022-04-11 17:37:57,897] {standard_task_runner.py:92} ERROR - Failed to execute job 1694 for task rm_task
Traceback (most recent call last):
  File "/home/airflow/.local/lib/python3.7/site-packages/airflow/task/task_runner/standard_task_runner.py", line 85, in _start_by_fork
    args.func(args, dag=self.dag)
  File "/home/airflow/.local/lib/python3.7/site-packages/airflow/cli/cli_parser.py", line 48, in command
    return func(*args, **kwargs)
  File "/home/airflow/.local/lib/python3.7/site-packages/airflow/utils/cli.py", line 92, in wrapper
    return f(*args, **kwargs)
  File "/home/airflow/.local/lib/python3.7/site-packages/airflow/cli/commands/task_command.py", line 298, in task_run
    _run_task_by_selected_method(args, dag, ti)
  File "/home/airflow/.local/lib/python3.7/site-packages/airflow/cli/commands/task_command.py", line 107, in _run_task_by_selected_method
    _run_raw_task(args, ti)
  File "/home/airflow/.local/lib/python3.7/site-packages/airflow/cli/commands/task_command.py", line 184, in _run_raw_task
    error_file=args.error_file,
  File "/home/airflow/.local/lib/python3.7/site-packages/airflow/utils/session.py", line 70, in wrapper
    return func(*args, session=session, **kwargs)
  File "/home/airflow/.local/lib/python3.7/site-packages/airflow/models/taskinstance.py", line 1329, in _run_raw_task
    self._execute_task_with_callbacks(context)
  File "/home/airflow/.local/lib/python3.7/site-packages/airflow/models/taskinstance.py", line 1455, in _execute_task_with_callbacks
    result = self._execute_task(context, self.task)
  File "/home/airflow/.local/lib/python3.7/site-packages/airflow/models/taskinstance.py", line 1511, in _execute_task
    result = execute_callable(context=context)
  File "/home/airflow/.local/lib/python3.7/site-packages/airflow/operators/bash.py", line 188, in execute
    f'Bash command failed. The command returned a non-zero exit code {result.exit_code}.'
airflow.exceptions.AirflowException: Bash command failed. The command returned a non-zero exit code 1.
[2022-04-11 17:37:57,916] {local_task_job.py:154} INFO - Task exited with return code 1
[2022-04-11 17:37:57,951] {local_task_job.py:264} INFO - 0 downstream tasks scheduled from follow-on schedule check
